<robot name="GEN3-6DOF_VISION_URDF_ARM_V01" version="1.0">
  <link name="Base_Link">
    <inertial>
      <origin xyz="-0.000648 -0.000166 0.084487" rpy="0 0 0" />
      <mass value="1.697" />
      <inertia ixx="0.004622" ixy="9E-06" ixz="6E-05" iyy="0.004495" iyz="9E-06" izz="0.002079" />
    </inertial>
    <visual>
      <origin xyz="0 0 0" rpy="0 0 0" />
      <geometry>
        <mesh filename="package://kortex_description/arms/gen3/6dof/meshes/base_link.STL" />
      </geometry>
      <material name="">
        <color rgba="0.75294 0.75294 0.75294 1" />
      </material>
    </visual>
    <collision>
      <origin xyz="0 0 0" rpy="0 0 0" />
      <geometry>
        <mesh filename="package://kortex_description/arms/gen3/6dof/meshes/base_link.STL" />
      </geometry>
    </collision>
  </link>
  <link name="Shoulder_Link">
    <inertial>
      <origin xyz="-2.3E-05 -0.010364 -0.07336" rpy="0 0 0" />
      <mass value="1.377" />
      <inertia ixx="0.00457" ixy="1E-06" ixz="2E-06" iyy="0.004831" iyz="0.000448" izz="0.001409" />
    </inertial>
    <visual>
      <origin xyz="0 0 0" rpy="0 0 0" />
      <geometry>
        <mesh filename="package://kortex_description/arms/gen3/6dof/meshes/shoulder_link.STL" />
      </geometry>
      <material name="">
        <color rgba="0.75294 0.75294 0.75294 1" />
      </material>
    </visual>
    <collision>
      <origin xyz="0 0 0" rpy="0 0 0" />
      <geometry>
        <mesh filename="package://kortex_description/arms/gen3/6dof/meshes/shoulder_link.STL" />
      </geometry>
    </collision>
  </link>
  <joint name="Actuator1" type="continuous">
    <origin xyz="0 0 0.156365" rpy="-3.1416 0.0 0.0" />
    <parent link="Base_Link" />
    <child link="Shoulder_Link" />
    <axis xyz="0 0 1" />
    <limit effort="39" velocity="0.8727" />
  </joint>
  <link name="Bicep_Link">
    <inertial>
      <origin xyz="3.5E-05 -0.208207 -0.01889" rpy="0 0 0" />
      <mass value="1.262" />
      <inertia ixx="0.046752" ixy="-9E-06" ixz="0" iyy="0.00085" iyz="-9.8E-05" izz="0.047188" />
    </inertial>
    <visual>
      <origin xyz="0 0 0" rpy="0 0 0" />
      <geometry>
        <mesh filename="package://kortex_description/arms/gen3/6dof/meshes/bicep_link.STL" />
      </geometry>
      <material name="">
        <color rgba="0.75294 0.75294 0.75294 1" />
      </material>
    </visual>
    <collision>
      <origin xyz="0 0 0" rpy="0 0 0" />
      <geometry>
        <mesh filename="package://kortex_description/arms/gen3/6dof/meshes/bicep_link.STL" />
      </geometry>
    </collision>
  </link>
  <joint name="Actuator2" type="fixed">
    <origin xyz="0 0.005375 -0.12843" rpy="1.5708 0.0 0.0" />
    <parent link="Shoulder_Link" />
    <child link="Bicep_Link" />
    <axis xyz="0 0 1" />
    <limit lower="-2.41" upper="2.41" effort="39" velocity="0.8727" />
  </joint>
  <link name="ForeArm_Link">
    <inertial>
      <origin xyz="1.8E-05 0.076168 -0.01397" rpy="0 0 0" />
      <mass value="0.93" />
      <inertia ixx="0.008292" ixy="-1E-06" ixz="0" iyy="0.000628" iyz="0.000432" izz="0.008464" />
    </inertial>
    <visual>
      <origin xyz="0 0 0" rpy="0 0 0" />
      <geometry>
        <mesh filename="package://kortex_description/arms/gen3/6dof/meshes/forearm_link.STL" />
      </geometry>
      <material name="">
        <color rgba="0.75294 0.75294 0.75294 1" />
      </material>
    </visual>
    <collision>
      <origin xyz="0 0 0" rpy="0 0 0" />
      <geometry>
        <mesh filename="package://kortex_description/arms/gen3/6dof/meshes/forearm_link.STL" />
      </geometry>
    </collision>
  </link>
  <joint name="Actuator3" type="revolute">
    <origin xyz="0 -0.41 0" rpy="3.1416 0 0" />
    <parent link="Bicep_Link" />
    <child link="ForeArm_Link" />
    <axis xyz="0 0 1" />
    <limit lower="-2.66" upper="2.66" effort="39" velocity="0.8727" />
  </joint>
  <link name="SphericalWrist1_Link">
    <inertial>
      <origin xyz="-1E-06 0.008486 -0.062937" rpy="0 0 0" />
      <mass value="0.6781" />
      <inertia ixx="0.001645" ixy="0" ixz="0" iyy="0.001666" iyz="-0.000234" izz="0.000389" />
    </inertial>
    <visual>
      <origin xyz="0 0 0" rpy="0 0 0" />
      <geometry>
        <mesh filename="package://kortex_description/arms/gen3/6dof/meshes/spherical_wrist_1_link.STL" />
      </geometry>
      <material name="">
        <color rgba="0.75294 0.75294 0.75294 1" />
      </material>
    </visual>
    <collision>
      <origin xyz="0 0 0" rpy="0 0 0" />
      <geometry>
        <mesh filename="package://kortex_description/arms/gen3/6dof/meshes/spherical_wrist_1_link.STL" />
      </geometry>
    </collision>
  </link>
  <joint name="Actuator4" type="fixed">
    <origin xyz="0 0.20843 -0.006375" rpy="1.5708 0.0 0.0" />
    <parent link="ForeArm_Link" />
    <child link="SphericalWrist1_Link" />
    <axis xyz="0 0 1" />
    <limit effort="9" velocity="0.8727" />
  </joint>
  <link name="SphericalWrist2_Link">
    <inertial>
      <origin xyz="-1E-06 0.046429 -0.008704" rpy="0 0 0" />
      <mass value="0.678" />
      <inertia ixx="0.001685" ixy="0" ixz="0" iyy="0.0004" iyz="0.000255" izz="0.001696" />
    </inertial>
    <visual>
      <origin xyz="0 0 0" rpy="0 0 0" />
      <geometry>
        <mesh filename="package://kortex_description/arms/gen3/6dof/meshes/spherical_wrist_2_link.STL" />
      </geometry>
      <material name="">
        <color rgba="0.75294 0.75294 0.75294 1" />
      </material>
    </visual>
    <collision>
      <origin xyz="0 0 0" rpy="0 0 0" />
      <geometry>
        <mesh filename="package://kortex_description/arms/gen3/6dof/meshes/spherical_wrist_2_link.STL" />
      </geometry>
    </collision>
  </link>
  <joint name="Actuator5" type="revolute">
    <origin xyz="0 -0.00017505 -0.10593" rpy="-1.5708 0.0 0.0" />
    <parent link="SphericalWrist1_Link" />
    <child link="SphericalWrist2_Link" />
    <axis xyz="0 0 1" />
    <limit lower="-2.23" upper="2.23" effort="9" velocity="0.8727" />
  </joint>
  <link name="Bracelet_Link">
    <inertial>
      <origin xyz="0.000281 0.011402 -0.029798" rpy="0 0 0" />
      <mass value="0.5" />
      <inertia ixx="0.000587" ixy="3E-06" ixz="3E-06" iyy="0.000369" iyz="-0.000118" izz="0.000609" />
    </inertial>
    <visual>
      <origin xyz="0 0 0" rpy="0 0 0" />
      <geometry>
        <mesh filename="package://kortex_description/arms/gen3/6dof/meshes/bracelet_with_vision_link.STL" />
      </geometry>
      <material name="">
        <color rgba="0.75294 0.75294 0.75294 1" />
      </material>
    </visual>
    <collision>
      <origin xyz="0 0 0" rpy="0 0 0" />
      <geometry>
        <mesh filename="package://kortex_description/arms/gen3/6dof/meshes/bracelet_with_vision_link.STL" />
      </geometry>
    </collision>
  </link>
  <joint name="Actuator6" type="fixed">
    <origin xyz="0 0.10593 -0.00017505" rpy="1.5708 0.0 0.0" />
    <parent link="SphericalWrist2_Link" />
    <child link="Bracelet_Link" />
    <axis xyz="0 0 1" />
    <limit effort="9" velocity="0.8727" />
  </joint>
  <link name="EndEffector_Link">
    <inertial>
      <origin xyz="0 0 0" rpy="0 0 0" />
      <mass value="0" />
      <inertia ixx="0" ixy="0" ixz="0" iyy="0" iyz="0" izz="0" />
    </inertial>
    <visual>
      <origin xyz="0 0 0" rpy="0 0 0" />
      <geometry>
        <mesh filename="package://kortex_description/arms/gen3/6dof/meshes/EndEffector_Link.STL" />
      </geometry>
      <material name="">
        <color rgba="0.75294 0.75294 0.75294 1" />
      </material>
    </visual>
    <collision>
      <origin xyz="0 0 0" rpy="0 0 0" />
      <geometry>
        <mesh filename="package://kortex_description/arms/gen3/6dof/meshes/EndEffector_Link.STL" />
      </geometry>
    </collision>
  </link>
  <joint name="EndEffector" type="fixed">
    <origin xyz="0 0 -0.061525" rpy="3.1416 0 -3.1416" />
    <parent link="Bracelet_Link" />
    <child link="EndEffector_Link" />
    <axis xyz="0 0 0" />
  </joint>

<!--################################################
  ########              gripper                  #####
  ####################################################-->

  <link name="robotiq_arg2f_base_link">
    <inertial>
      <origin rpy="0 0 0" xyz="8.625E-08 -4.6583E-06 0.03145"/>
      <mass value="0.22652"/>
      <inertia ixx="0.00020005" ixy="-4.2442E-10" ixz="-2.9069E-10" iyy="0.00017832" iyz="-3.4402E-08" izz="0.00013478"/>
    </inertial>
    <visual>
      <origin rpy="0 0 0" xyz="0 0 0"/>
      <geometry>
        <mesh filename="package://meshes/robotiq_85/visual/robotiq_arg2f_85_base_link.dae" scale="0.001 0.001 0.001"/>
      </geometry>
      <material name="LightGrey">
        <color rgba="0.0 0.0 0.0 1.0"/>
      </material>
    </visual>
    <collision>
      <origin rpy="0 0 0" xyz="0 0 0"/>
      <geometry>
        <mesh filename="package://meshes/robotiq_85/collision/robotiq_arg2f_base_link.stl"/>
      </geometry>
    </collision>
  </link>
  <joint name="finger_joint" type="revolute">
    <origin rpy="0 0 3.14159265359" xyz="0 -0.0306011 0.054904"/>
    <parent link="robotiq_arg2f_base_link"/>
    <child link="left_outer_knuckle"/>
    <axis xyz="1 0 0"/>
    <limit effort="1000" lower="0" upper="0.8" velocity="2.0"/>
  </joint>
  <link name="left_outer_knuckle">
    <inertial>
        <origin xyz="-0.000200000000003065 0.0199435877845359 0.0292245259211331" rpy="0 0 0" />
        <mass value="0.00853198276973456" />
        <inertia ixx="2.89328108496468E-06" ixy="-1.57935047237397E-19" ixz="-1.93980378593255E-19" iyy="1.86719750325683E-06" iyz="-1.21858577871576E-06" izz="1.21905238907251E-06" />
        </inertial>
    <visual>
      <origin rpy="0 0 0" xyz="0 0 0"/>
      <geometry>
        <mesh filename="package://meshes/robotiq_85/visual/robotiq_arg2f_85_outer_knuckle.dae" scale="0.001 0.001 0.001"/>
      </geometry>
      <material name="Light Grey">
        <color rgba="0 0 0 1"/>
      </material>
    </visual>
    <collision>
      <origin rpy="0 0 0" xyz="0 0 0"/>
      <geometry>
        <mesh filename="package://meshes/robotiq_85/collision/robotiq_arg2f_85_outer_knuckle.dae" scale="0.001 0.001 0.001"/>
      </geometry>
    </collision>
  </link>
  <joint name="left_outer_finger_joint" type="fixed">
    <origin rpy="0 0 0" xyz="0 0.0315 -0.0041"/>
    <parent link="left_outer_knuckle"/>
    <child link="left_outer_finger"/>
    <axis xyz="1 0 0"/>
  </joint>
  <link name="left_outer_finger">
    <inertial>
        <origin xyz="0.00030115855001899 0.0373907951953854 -0.0208027427000385" rpy="0 0 0" />
        <mass value="0.022614240507152" />
        <inertia ixx="1.52518312458174E-05" ixy="9.76583423954399E-10" ixz="-5.43838577022588E-10" iyy="6.17694243867776E-06" iyz="6.78636130740228E-06" izz="1.16494917907219E-05" />
        </inertial>
    <visual>
      <origin rpy="0 0 0" xyz="0 0 0"/>
      <geometry>
        <mesh filename="package://meshes/robotiq_85/visual/robotiq_arg2f_85_outer_finger.dae" scale="0.001 0.001 0.001"/>
      </geometry>
      <material name="LightGrey">
        <color rgba="0 0 0 1.0"/>
      </material>
    </visual>
    <collision>
      <origin rpy="0 0 0" xyz="0 0 0"/>
      <geometry>
        <mesh filename="package://meshes/robotiq_85/collision/robotiq_arg2f_85_outer_finger.dae" scale="0.001 0.001 0.001"/>
      </geometry>
    </collision>
  </link>
  <joint name="left_inner_finger_joint" type="revolute">
    <origin rpy="0 0 0" xyz="0 0.0061 0.0471"/>
    <parent link="left_outer_finger"/>
    <child link="left_inner_finger"/>
    <axis xyz="1 0 0"/>
    <limit effort="1000" lower="-0.8757" upper="0" velocity="2.0"/>
    <mimic joint="finger_joint" multiplier="-1" offset="0"/>
  </joint>
  <link name="left_inner_finger">
    <inertial>
        <origin xyz="0.000299999999999317 0.0160078233491243 -0.0136945669206257" rpy="0 0 0" />
        <mass value="0.0104003125914103" />
        <inertia ixx="2.71909453810972E-06" ixy="1.35402465472579E-21" ixz="-7.1817349065269E-22" iyy="7.69100314106116E-07" iyz="6.74715432769696E-07" izz="2.30315190420171E-06" />
        </inertial>
    <visual>
      <origin rpy="0 0 0" xyz="0 0 0"/>
      <geometry>
        <mesh filename="package://meshes/robotiq_85/visual/robotiq_arg2f_85_inner_finger.dae" scale="0.001 0.001 0.001"/>
      </geometry>
      <material name="LightGrey">
        <color rgba="0 0 0 1.0"/>
      </material>
    </visual>
    <collision>
      <origin rpy="0 0 0" xyz="0 0 0"/>
      <geometry>
        <mesh filename="package://meshes/robotiq_85/collision/robotiq_arg2f_85_inner_finger.dae" scale="0.001 0.001 0.001"/>
      </geometry>
    </collision>
  </link>
  <joint name="left_inner_finger_pad_joint" type="fixed">
    <origin rpy="0 0 0" xyz="0 -0.0220203446692936 0.03242"/>
    <parent link="left_inner_finger"/>
    <child link="left_inner_finger_pad"/>
    <axis xyz="0 0 1"/>
  </joint>
  <link name="left_inner_finger_pad">
    <inertial>
      <mass value="1."/>
      <inertia ixx="1E-10" ixy="1E-10" ixz="1E-10" iyy="1E-10" iyz="1E-10" izz="1E-10"/>
    </inertial>
    <visual>
      <origin rpy="0 0 0" xyz="0 0 0"/>
      <geometry>
        <box size="0.022 0.00635 0.0375"/>
      </geometry>
      <material name="LightGrey">
        <color rgba="0.0 0.0 0.0 1.0"/>
      </material>
    </visual>
    <collision>
      <origin rpy="0 0 0" xyz="0 0 0"/>
      <geometry>
        <box size="0.022 0.00635 0.0375"/>
      </geometry>
      <material name="LightGrey">
        <color rgba="0.0 0.0 0.0 1"/>
      </material>
    </collision>
  </link>
  <joint name="left_inner_knuckle_joint" type="revolute">
    <!-- <origin xyz="0 ${reflect * -0.0127} 0.06142" rpy="${pi / 2 + .725} 0 ${(reflect - 1) * pi / 2}" /> -->
    <origin rpy="0 0 3.14159265359" xyz="0 -0.0127 0.06142"/>
    <parent link="robotiq_arg2f_base_link"/>
    <child link="left_inner_knuckle"/>
    <axis xyz="1 0 0"/>
    <limit effort="1000" lower="0" upper="0.8757" velocity="2.0"/>
    <mimic joint="finger_joint" multiplier="1" offset="0"/>
  </joint>
  <link name="left_inner_knuckle">
    <inertial>
        <origin xyz="0.000123011831763771 0.0507850843201817 0.00103968640075166" rpy="0 0 0" />
       <mass value="0.0271177346495152" />
        <inertia ixx="2.61910379223783E-05" ixy="-2.43616858946494E-07" ixz="-6.37789906117123E-09" iyy="2.8270243746167E-06" iyz="-5.37200748039765E-07" izz="2.83695868220296E-05" />
        </inertial>
    <visual>
      <origin rpy="0 0 0" xyz="0 0 0"/>
      <geometry>
        <mesh filename="package://meshes/robotiq_85/visual/robotiq_arg2f_85_inner_knuckle.dae" scale="0.001 0.001 0.001"/>
      </geometry>
      <material name="LightGrey">
        <color rgba="0 0 0 1.0"/>
      </material>
    </visual>
    <collision>
      <origin rpy="0 0 0" xyz="0 0 0"/>
      <geometry>
        <mesh filename="package://meshes/robotiq_85/collision/robotiq_arg2f_85_inner_knuckle.dae" scale="0.001 0.001 0.001"/>
      </geometry>
    </collision>
  </link>
  <joint name="right_outer_knuckle_joint" type="revolute">
    <origin rpy="0 0 0" xyz="0 0.0306011 0.054904"/>
    <parent link="robotiq_arg2f_base_link"/>
    <child link="right_outer_knuckle"/>
    <axis xyz="1 0 0"/>
    <limit effort="1000" lower="0" upper="0.81" velocity="2.0"/>
    <mimic joint="finger_joint" multiplier="1" offset="0"/>
  </joint>
  <link name="right_outer_knuckle">
    <inertial>
        <origin xyz="-0.000200000000003065 0.0199435877845359 0.0292245259211331" rpy="0 0 0" />
        <mass value="0.00853198276973456" />
        <inertia ixx="2.89328108496468E-06" ixy="-1.57935047237397E-19" ixz="-1.93980378593255E-19" iyy="1.86719750325683E-06" iyz="-1.21858577871576E-06" izz="1.21905238907251E-06" />
        </inertial>
    <visual>
      <origin rpy="0 0 0" xyz="0 0 0"/>
      <geometry>
        <mesh filename="package://meshes/robotiq_85/visual/robotiq_arg2f_85_outer_knuckle.dae" scale="0.001 0.001 0.001"/>
      </geometry>
      <material name="LightGrey">
        <color rgba="0.0 0.0 0.0 1"/>
      </material>
    </visual>
    <collision>
      <origin rpy="0 0 0" xyz="0 0 0"/>
      <geometry>
        <mesh filename="package://meshes/robotiq_85/collision/robotiq_arg2f_85_outer_knuckle.dae" scale="0.001 0.001 0.001"/>
      </geometry>
    </collision>
  </link>
  <joint name="right_outer_finger_joint" type="fixed">
    <origin rpy="0 0 0" xyz="0 0.0315 -0.0041"/>
    <parent link="right_outer_knuckle"/>
    <child link="right_outer_finger"/>
    <axis xyz="1 0 0"/>
  </joint>
  <link name="right_outer_finger">
    <inertial>
        <origin xyz="0.00030115855001899 0.0373907951953854 -0.0208027427000385" rpy="0 0 0" />
        <mass value="0.022614240507152" />
        <inertia ixx="1.52518312458174E-05" ixy="9.76583423954399E-10" ixz="-5.43838577022588E-10" iyy="6.17694243867776E-06" iyz="6.78636130740228E-06" izz="1.16494917907219E-05" />
        </inertial>
    <visual>
      <origin rpy="0 0 0" xyz="0 0 0"/>
      <geometry>
        <mesh filename="package://meshes/robotiq_85/visual/robotiq_arg2f_85_outer_finger.dae" scale="0.001 0.001 0.001"/>
      </geometry>
      <material name="LightGrey">
        <color rgba="0.0 0.0 0.0 1.0"/>
      </material>
    </visual>
    <collision>
      <origin rpy="0 0 0" xyz="0 0 0"/>
      <geometry>
        <mesh filename="package://meshes/robotiq_85/collision/robotiq_arg2f_85_outer_finger.dae" scale="0.001 0.001 0.001"/>
      </geometry>
    </collision>
  </link>
  <joint name="right_inner_finger_joint" type="revolute">
    <origin rpy="0 0 0" xyz="0 0.0061 0.0471"/>
    <parent link="right_outer_finger"/>
    <child link="right_inner_finger"/>
    <axis xyz="1 0 0"/>
    <limit effort="1000" lower="-0.8757" upper="0" velocity="2.0"/>
    <mimic joint="finger_joint" multiplier="-1" offset="0"/>
  </joint>
  <link name="right_inner_finger">
    <inertial>
        <origin xyz="0.000299999999999317 0.0160078233491243 -0.0136945669206257" rpy="0 0 0" />
        <mass value="0.0104003125914103" />
        <inertia ixx="2.71909453810972E-06" ixy="1.35402465472579E-21" ixz="-7.1817349065269E-22" iyy="7.69100314106116E-07" iyz="6.74715432769696E-07" izz="2.30315190420171E-06" />
        </inertial>
    <visual>
      <origin rpy="0 0 0" xyz="0 0 0"/>
      <geometry>
        <mesh filename="package://meshes/robotiq_85/visual/robotiq_arg2f_85_inner_finger.dae" scale="0.001 0.001 0.001"/>
      </geometry>
      <material name="LightGrey">
        <color rgba="0.0 0.0 0.0 1"/>
      </material>
    </visual>
    <collision>
      <origin rpy="0 0 0" xyz="0 0 0"/>
      <geometry>
        <mesh filename="package://meshes/robotiq_85/collision/robotiq_arg2f_85_inner_finger.dae" scale="0.001 0.001 0.001"/>
      </geometry>
    </collision>
  </link>
  <joint name="right_inner_finger_pad_joint" type="fixed">
    <origin rpy="0 0 0" xyz="0 -0.0220203446692936 0.03242"/>
    <parent link="right_inner_finger"/>
    <child link="right_inner_finger_pad"/>
    <axis xyz="0 0 1"/>
  </joint>
  <link name="right_inner_finger_pad">
    <inertial>
      <mass value="1"/>
      <inertia ixx="1E-10" ixy="1E-10" ixz="1E-10" iyy="1E-10" iyz="1E-10" izz="1E-10"/>
    </inertial>
    <visual>
      <origin rpy="0 0 0" xyz="0 0 0"/>
      <geometry>
        <box size="0.022 0.00635 0.0375"/>
      </geometry>
      <material name="LightGrey">
        <color rgba="0.0 0.0 0.0 1.0"/>
      </material>
    </visual>
    <collision>
      <origin rpy="0 0 0" xyz="0 0 0"/>
      <geometry>
        <box size="0.022 0.00635 0.0375"/>
      </geometry>
      <material name="LightGrey">
        <color rgba="0.0 0.0 0.0 1.0"/>
      </material>
    </collision>
  </link>
  <joint name="right_inner_knuckle_joint" type="revolute">
    <!-- <origin xyz="0 ${reflect * -0.0127} 0.06142" rpy="${pi / 2 + .725} 0 ${(reflect - 1) * pi / 2}" /> -->
    <origin rpy="0 0 0.0" xyz="0 0.0127 0.06142"/>
    <parent link="robotiq_arg2f_base_link"/>
    <child link="right_inner_knuckle"/>
    <axis xyz="1 0 0"/>
    <limit effort="1000" lower="0" upper="0.8757" velocity="2.0"/>
    <mimic joint="finger_joint" multiplier="1" offset="0"/>
  </joint>
  <link name="right_inner_knuckle">
    <inertial>
        <origin xyz="0.000123011831763771 0.0507850843201817 0.00103968640075166" rpy="0 0 0" />
       <mass value="0.0271177346495152" />
        <inertia ixx="2.61910379223783E-05" ixy="-2.43616858946494E-07" ixz="-6.37789906117123E-09" iyy="2.8270243746167E-06" iyz="-5.37200748039765E-07" izz="2.83695868220296E-05" />
        </inertial>
    <visual>
      <origin rpy="0 0 0" xyz="0 0 0"/>
      <geometry>
        <mesh filename="package://meshes/robotiq_85/visual/robotiq_arg2f_85_inner_knuckle.dae" scale="0.001 0.001 0.001"/>
      </geometry>
      <material name="LightGrey">
        <color rgba="0 0 0 1.0"/>
      </material>
    </visual>
    <collision>
      <origin rpy="0 0 0" xyz="0 0 0"/>
      <geometry>
        <mesh filename="package://meshes/robotiq_85/collision/robotiq_arg2f_85_inner_knuckle.dae" scale="0.001 0.001 0.001"/>
      </geometry>
    </collision>
  </link>

  <!--################################################
  ########          connect model                #####
  ####################################################-->

  <link name="world"/>
  <!-- connect gripper to arm -->
  <joint name="robotiq_85_base_joint" type="fixed">
    <parent link="EndEffector_Link"/>
    <child link="robotiq_arg2f_base_link"/>
    <origin rpy="0 0 1.57079632679" xyz="0 0 0"/>
  </joint>

<!--  <joint name="arm_gripper_joint" type="fixed">-->
<!--    <parent link="ee_link"/>-->
<!--    <child link="robotiq_140_robotiq_arg2f_base_link"/>-->
<!--    <origin rpy="-1.57 1.57 -1.57" xyz="0.0 0.0 0.0"/>-->
<!--  </joint>-->

  <!-- connect arm to world -->
  <joint name="world_arm_joint" type="fixed">
    <parent link="world"/>
    <child link="Base_Link"/>
    <origin rpy="0.0 0.0 0" xyz="0 0 0"/>
  </joint>

</robot>